<?xml version="1.0"?>
<robot name="kobuki_parameters" xmlns:xacro="http://ros.org/wiki/xacro">
    
    <xacro:property name="M_PI" value="3.1415926535897931" /> 
  
    <material name="Black">
        <color rgba="0.22 0.22 0.22 1.0"/>
    </material>
  
    <!-- Base Link Macro -->
    <xacro:macro 
    name="link_base_kobuki" 
    params="name visual_rpy visual_xyz inertial_xyz inertial_rpy 
            collision_xyz collision_rpy meshfile 
            mass ixx ixy ixz iyy iyz izz cylinder_length cylinder_radius">

        <link name="${name}">
            <visual>
                <origin rpy="${visual_rpy}" xyz="${visual_xyz}" />
                <geometry>
                    <mesh filename="${meshfile}"/>
                </geometry>
                <material name="Black"/>
            </visual> 
        
            <inertial>
                <mass value="${mass}" />
                <origin rpy="${inertial_rpy}" xyz="${inertial_xyz}" />
                <inertia ixx="${ixx}" ixy="${ixy}" ixz="${ixz}" iyy="${iyy}" iyz="${iyz}" izz="${izz}" />
            </inertial>

            <collision>
                <origin rpy="${collision_rpy}" xyz="${collision_xyz}" />
                <geometry>
                    <cylinder length="${cylinder_length}" radius="${cylinder_radius}"/>
                </geometry>
            </collision>
        </link>
    </xacro:macro>

    <!-- Traction Wheels Link Macro -->
    <xacro:macro 
    name="wheel_kobuki" 
    params="name 
            joint_origin_xyz joint_origin_rpy joint_axis_xyz
            visual_rpy visual_xyz inertial_xyz inertial_rpy 
            collision_xyz collision_rpy meshfile 
            mass ixx ixy ixz iyy iyz izz cylinder_length cylinder_radius">

        <joint name="${name}_joint" type="continuous">
            <parent link="base_link"/>
            <child link="${name}_link"/>
            <origin xyz="${joint_origin_xyz}" rpy="${joint_origin_rpy}"/>
            <axis xyz="${joint_axis_xyz}"/>
        </joint>

        <link name="${name}_link">
            <visual>
                <origin rpy="${visual_rpy}" xyz="${visual_xyz}" />
                <geometry>
                    <mesh filename="${meshfile}"/>
                </geometry>
                <material name="Black"/>
            </visual> 
        
            <inertial>
                <mass value="${mass}" />
                <origin rpy="${inertial_rpy}" xyz="${inertial_xyz}" />
                <inertia ixx="${ixx}" ixy="${ixy}" ixz="${ixz}" iyy="${iyy}" iyz="${iyz}" izz="${izz}" />
            </inertial>

            <collision>
                <origin rpy="${collision_rpy}" xyz="${collision_xyz}" />
                <geometry>
                    <!-- <cylinder length="${cylinder_length}" radius="${cylinder_radius}"/> -->
                    <sphere radius="${cylinder_radius}"/>
                </geometry>
            </collision>
        </link>

        <!-- Friction values -->
        <!-- Cambiar valores de mu1, mu2, fdir1 -->
        <gazebo reference="${name}_link">
			<mu1>0.01</mu1>
            <mu2>1</mu2>
            <fdir1>0 0 1</fdir1>
		</gazebo>

		<transmission name="${name}_tranmission">
            <type>transmission_interface/SimpleTransmission</type>
            <joint name="${name}_joint">
                <hardwareInterface>hardware_interface/VelocityJointInterface</hardwareInterface>
            </joint>
            <actuator name="${name}_actuator">
                <mechanicalReduction>1</mechanicalReduction>
            </actuator>
         </transmission>
    </xacro:macro>

    <!-- Castor Wheels Link Macro -->
    <xacro:macro 
    name="castor_wheel_kobuki" 
    params="name 
            joint_origin_xyz joint_origin_rpy 
            inertial_xyz inertial_rpy collision_xyz collision_rpy  
            mass ixx ixy ixz iyy iyz izz cylinder_length cylinder_radius">

        <joint name="${name}_joint" type="fixed">
            <parent link="base_link"/>
            <child link="${name}_link"/>
            <origin xyz="${joint_origin_xyz}" rpy="${joint_origin_rpy}"/>
        </joint>

        <link name="${name}_link">
            <inertial>
                <mass value="${mass}" />
                <origin rpy="${inertial_rpy}" xyz="${inertial_xyz}" />
                <inertia ixx="${ixx}" ixy="${ixy}" ixz="${ixz}" iyy="${iyy}" iyz="${iyz}" izz="${izz}" />
            </inertial>

            <collision>
                <origin rpy="${collision_rpy}" xyz="${collision_xyz}" />
                <geometry>
                    <!-- <cylinder length="${cylinder_length}" radius="${cylinder_radius}"/> -->
                    <sphere radius="${cylinder_radius}"/>
                </geometry>
            </collision>

        </link>
    </xacro:macro>


</robot>